Workbook
Name _Hlk230767011: 'Anexo- Intercambios & Ruedas'!$B$24

Sheet Informe Gestión Mensual
A1: DIRECCIÓN DE DESARROLLO TURÍSTICO
A2: PLAN MENSUAL DE TRABAJO
A3: Mes: MAYO-2026
A5: No. | B5: INDICADOR META POA | C5: Ejecución Mes Anterior | D5: AVANCE CUANTITATIVO | H5: AVANCE CUALITATIVO | I5: IMPACTO ESPERADO | J5: METAS ATRASADAS
D6: Ejecución del Mes | E6: Ejecución Acumulada enero- septiembre | F6: Programación Acumulada enero- DICIEMBRE | G6: Porcentaje de Cumplimiento | J6: Principales causas | K6: Plan de Medidas
A7: 1 | B7: 13,550 protagonistas de pequeños y medianos negocios turísticos capacitados. | C7: 11141 | D7: =+TERRITORIALIZACIÓN!J21 -> 1188 | E7: =C7+D7 -> 12329 | F7: 13500 | G7: =+E7/F7 -> 0.91325926 | H7: Del mes de enero a septiembre se han realizado 529 talleres, capacitando a un total de 12,329 protagonistas, de los cuales 4,408 son hombres y 7,921 mujeres. Durante el mes de septiembre se capacitaron 1,188 protagonistas mediante la realización de 49 talleres, en los que se abordaron temas como: Elaboración de Batidos Naturales y Nutritivos, Conservación del Patrimonio Natural y Cultural, Elaboración de Cócteles y Aperitivos, Atención al Cliente, Pastelería Salada, Redes Sociales, Liderazgo y Emprendedurismo en el Turismo, Elaboración de Planes de Negocios, Técnicas de Servicio en Alimentos y Bebidas, Gestión Empresarial, Servicio de Habitaciones, Agenda Digital e Inteligencia Artificial, Gestión de Crisis en el Turismo, Técnicas de Recepción, Técnicas Culinarias para Eventos Navideños, Protagonismo de la Mujer en el Sector Turismo, Innovación y Emprendimiento Turístico, Manipulación Higiénica de Alimentos y Bebidas, Montaje y Protocolo de Eventos, Limpieza y Arreglo de Habitaciones, Cocina Nicaragüense y Elaboración de Cócteles Artesanales, entre otros. | I7: Fortalecer las capacidades técnicas de colaboradores, guías turísticos y empresarios turísticos del sector, para la mejora de la calidad del servicio de cara a temporadas altas.
A8: 2 | B8: 7 Intercambios de Experiencias realizados | C8: 1 | D8: 1 | E8: =+C8+D8 -> 2 | F8: 7 | G8: =+E8/F8 -> 0.28571429 | H8: En el mes de mayo no se realizó Intercambio de Experiencias.
A9: 3 | B9: 7,152 Empresas Turísticas Autorizadas por INTUR. | C9: 5992 | D9: 420 | E9: =+C9+D9 -> 6412 | F9: 6483 | G9: =+E9/F9 -> 0.98904828 | H9: Para el mes de mayo se autorizaron 420 empresas turísticas a nivel nacional. | I9: Mayor número de Empresas turísticas formalizadas en el periodo que corresponde de según la ley 1210. | J9: Las empresas están en el proceso de tramite para obtener los requisitos ante otras instituciones para lograr presentar sus requisitos ante INTUR .
A10: 4 | B10: 8,297 Empresas Turísticas asistidas en elaboración de Planes de Mejora. | C10: 8410 | D10: 180 | E10: =+C10+D10 -> 8590 | F10: 8067 | G10: =+E10/F10 -> 1.064832 | H10: Para el mes de mayo 180 empresas turísticas fueron asistidas en la elaboración de planes de mejoras a nivel nacional, como resultado de las inconformidades identificas durante la aplicación de las herramientas de clasificación y categorización, los planes de mejora son la guía que facilita el INTUR para que las empresas logren aumentar de categoría y ser parte de la oferta turistica nacional. | I10: Empresas turistícas mantienen su categorias y en otros casos aumento de categoría, para formar parte de la oferta turistica del país.
A11: 5 | B11: 325 Empresas Turísticas que suben de categoría. | C11: 362 | D11: 1 | E11: =+C11+D11 -> 363 | F11: 325 | G11: =+E11/F11 -> 1.1169231 | H11: Para el mes de mayo 1 empresa turística aumento de categoría, como resultado del asesoramiento de los inspectores turisticos a nivel nacional, lo que permitió que las empresas cumplieran con los planes de mejoras elaborados en el año 2025, para lograr obtener el aumento de categiría en el presente año. | I11: Aumento de empresas con categoría en la oferta tursitica nacional.
A12: 6 | B12: 7,152 Códigos de Conducta suscritos entre empresas turísticas autorizadas e INTUR. | C12: 5992 | D12: 420 | E12: =+C12+D12 -> 6412 | F12: 6483 | G12: =+E12/F12 -> 0.98904828 | H12: para el mes de mayo 420 empresas turísticas suscribieron la firma de códigos de conducta, como compromiso del sector turistico encontra de la explotación sexual de nuestros niños, niñas y adolescente en viajes y turismo. | I12: Sector turistico comprometido con el cuido y protección de los niños, niñas y adolentes para que no sean victimas de la explotación sexual. | J12: Este indicador depende de empresas autorizadas, al estar en proceso de tramitologia por parte de las empresas ha ocasionado el retraso en el cumplimiento de este indicador.
A13: 7 | B13: 835 Protagonistas de pequeños y medianos negocios turísticos sensibilizados en ESNNA | C13: 535 | D13: 237 | E13: =SUM(C13:D13) -> 772 | F13: 835 | G13: =+E13/F13 -> 0.9245509 | H13: En el mes de mayo se realizaron 8 talleres de prevención de ESNNA: 1 en Estelí, 1 en Jinotega, 2 en Managua, 1 en Nueva Segovia, 1 en Madriz, 1 en Rivas y 1 en Granada. | I13: Fortalecer las capacidades de los prestadores de servicios turísticos, en temas de prevención de ESNNA.
A14: 8 | B14: 835 Empresas Turísticas abren negocio por primera vez | C14: 518 | D14: 143 | E14: =+C14+D14 -> 661 | F14: 474 | G14: =+E14/F14 -> 1.3945148 | H14: para el mes de mayo 143 empresas turisticas abrieron por primera vez, lo que ocasiona aumento y diversificación del sector, como resultado de la inversion nacional. | I14: Aumento de empresas turisticas y diversificación de oferta.
A15: 9 | B15: 4,027 Empleos generados por las nuevas empresas turísticas que abren por primera vez. | C15: 2592 | D15: 804 | E15: =+C15+D15 -> 3396 | F15: 2165 | G15: =+E15/F15 -> 1.5685912 | H15: Para el mes de mayo se registraron 804 empleos nuevos generados por las empresas que abren por primera vez, haciendo notorio la reactivación del sector. | I15: Actividad turistica como uno de los principales generadores de empleos
A16: 10 | B16: 729 Nuevas habitaciones habilitadas por las empresas turísticas. | C16: 928 | D16: 141 | E16: =+C16+D16 -> 1069 | F16: 573 | G16: =+E16/F16 -> 1.8656195 | H16: Para el mes de mayo se habilitaron 141 habitaciones, como resultado de empesas de las actividades de hospedería que aperturaron por primera vez, asi como tambien empresas de hospedería que aumentaron el número de habitaciones habilitadas. | I16: Aumento de habitaciones y camas al servicio, de cara al aumento de pernoctación de los turistas.
A17: 12 | B17: 290 Empresas Turísticas que obtienen el Distintivo de Calidad. | D17: =+TERRITORIALIZACIÓN!L220 -> 0 | E17: =+C17+D17 -> 0 | F17: 0 | G17: =+E17/F17 -> #DIV/0! | H17: Técnicas de las 5´s : 1 | I17: Empresas turísticas con distintivo de calidad, con procesos internos claros que ofertan servicio con calidad.
A18: 11 | B18: 23 Ruedas de Negocios realizadas | C18: 5 | D18: 3 | E18: =+C18+D18 -> 8 | F18: 23 | G18: =+E18/F18 -> 0.34782609 | H18: En el mes de mayo se realizaron 3 Rueda de Negocios: 1 con empresas en Gestión de Desarrollo Digital en Managua, 2 con tour operadoras en Managua y Madriz. | I18: Promover el enlazamiento y mejorar la asociatividad entre el sector turístico y el productivo.
A19: 12 | B19: 207 Empresas Turísticas asistidas para obtener distintivo de calidad | C19: 0 | D19: 0 | E19: =+C19+D19 -> 0 | G19: =+E19/F19 -> #DIV/0! | I19: Empresas turísticas con distintivo de calidad, con procesos internos claros, organizados y que ofertan servicio con calidad.

Sheet TERRITORIALIZACIÓN
A1: META ANUAL: | B1: =+'Informe Gestión Mensual'!B7 -> 13,550 protagonistas de pequeños y medianos negocios turísticos capacitados.
A3: DEPARTAMENTO / MES | B3: ENERO | C3: FEBRERO | D3: MARZO | E3: ABRIL | F3: MAYO | G3: JUNIO | H3: JULIO | I3: AGOSTO | J3: SEPTIEMBRE | K3: OCTUBRE | L3: NOVIEMBRE | M3: DICIEMBRE | N3: TOTAL
A4: BOACO | B4: 45 | C4: 42 | D4: 64 | E4: 58 | F4: 24 | G4: 26 | H4: 45 | I4: 52 | J4: 48 | N4: =SUM(B4:M4) -> 404
A5: CARAZO | B5: 47 | C5: 59 | D5: 56 | E5: 43 | F5: 61 | G5: 68 | H5: 29 | I5: 77 | J5: 99 | N5: =SUM(B5:M5) -> 539
A6: CHINANDEGA | B6: 33 | C6: 112 | D6: 199 | E6: 168 | F6: 90 | G6: 52 | H6: 55 | I6: 100 | J6: 149 | N6: =SUM(B6:M6) -> 958
A7: CHONTALES | B7: 28 | C7: 89 | D7: 59 | E7: 87 | F7: 49 | G7: 44 | H7: 58 | I7: 63 | J7: 112 | N7: =SUM(B7:M7) -> 589
A8: ESTELÍ | B8: 22 | C8: 44 | D8: 64 | E8: 25 | F8: 137 | G8: 46 | H8: 80 | I8: 44 | J8: 73 | N8: =SUM(B8:M8) -> 535
A9: GRANADA | B9: 44 | C9: 56 | D9: 144 | E9: 61 | F9: 78 | G9: 91 | H9: 104 | I9: 127 | J9: 49 | N9: =SUM(B9:M9) -> 754
A10: JINOTEGA | B10: 26 | C10: 21 | D10: 51 | E10: 27 | F10: 17 | G10: 47 | H10: 66 | I10: 15 | J10: 0 | N10: =SUM(B10:M10) -> 270
A11: LEÓN | B11: 39 | C11: 101 | D11: 139 | E11: 83 | F11: 227 | G11: 150 | H11: 123 | I11: 109 | J11: 23 | N11: =SUM(B11:M11) -> 994
A12: MADRIZ | B12: 94 | C12: 65 | D12: 112 | E12: 50 | F12: 54 | G12: 57 | H12: 134 | I12: 73 | J12: 74 | N12: =SUM(B12:M12) -> 713
A13: MANAGUA | B13: 200 | C13: 268 | D13: 157 | E13: 168 | F13: 153 | G13: 68 | H13: 120 | I13: 266 | J13: 120 | N13: =SUM(B13:M13) -> 1520
A14: MASAYA | B14: 160 | C14: 246 | D14: 184 | E14: 58 | F14: 174 | G14: 91 | H14: 69 | I14: 137 | J14: 35 | N14: =SUM(B14:M14) -> 1154
A15: MATAGALPA | B15: 29 | C15: 95 | D15: 248 | E15: 121 | F15: 99 | G15: 56 | H15: 44 | I15: 16 | J15: 49 | N15: =SUM(B15:M15) -> 757
... A20: RIVAS | B20: 48 | C20: 199 | D20: 190 | E20: 76 | F20: 94 | G20: 30 | H20: 37 | I20: 97 | J20: 115 | N20: =SUM(B20:M20) -> 886
A21: } | B21: =SUM(B4:B20) -> 994 | C21: =SUM(C4:C20) -> 1762 | D21: =SUM(D4:D20) -> 1938 | E21: =SUM(E4:E20) -> 1302 | F21: =SUM(F4:F20) -> 1503 | G21: =SUM(G4:G20) -> 1029 | H21: =SUM(H4:H20) -> 1151 | I21: =SUM(I4:I20) -> 1462 | ... M21: =SUM(M4:M20) -> 0 | N21: =SUM(B21:M21) -> 12329
A23: META ANUAL: | B23: 400 de protagonistas de pequeños y medianos negocios turísticos sensibilizados en ESNNA
A25: DEPARTAMENTO / MES | B25: ENERO | C25: FEBRERO | D25: MARZO | E25: ABRIL | F25: MAYO | G25: JUNIO | H25: JULIO | I25: AGOSTO | J25: SEPTIEMBRE | K25: OCTUBRE | L25: NOVIEMBRE | M25: DICIEMBRE | N25: TOTAL
A26: BOACO | B26: 1 | N26: =SUM(B26:M26) -> 1
A27: CARAZO | N27: =SUM(B27:M27) -> 0
A28: CHINANDEGA | N28: =SUM(B28:M28) -> 0
A29: CHONTALES | N29: =SUM(B29:M29) -> 0
A30: ESTELÍ | C30: 1 | F30: 1 | N30: =SUM(B30:M30) -> 2
A31: GRANADA | B31: 1 | F31: 1 | N31: =SUM(B31:M31) -> 2
A32: JINOTEGA | C32: 1 | D32: 1 | F32: 1 | N32: =SUM(B32:M32) -> 3
A33: LEÓN | D33: 1 | N33: =SUM(B33:M33) -> 1
A34: MADRIZ | C34: 1 | F34: 1 | N34: =SUM(B34:M34) -> 2
A35: MANAGUA | C35: 2 | D35: 2 | E35: 2 | F35: 2 | N35: =SUM(B35:M35) -> 8
A36: MASAYA | C36: 1 | N36: =SUM(B36:M36) -> 1
A37: MATAGALPA | E37: 1 | N37: =SUM(B37:M37) -> 1
A38: NUEVA SEGOVIA | F38: 1 | N38: =SUM(B38:M38) -> 1
A39: RACCS | N39: =SUM(B39:M39) -> 0
A40: RACCN | E40: 2 | N40: =SUM(B40:M40) -> 2
A41: RÍO SAN JUAN | C41: 1 | N41: =SUM(B41:M41) -> 1
A42: RIVAS | E42: 1 | F42: 1 | N42: =SUM(B42:M42) -> 2
A43: TOTAL | B43: =SUM(B26:B42) -> 2 | C43: =SUM(C26:C42) -> 7 | D43: =SUM(D26:D42) -> 4 | E43: =SUM(E26:E42) -> 6 | F43: =SUM(F26:F42) -> 8 | G43: =SUM(G26:G42) -> 0 | H43: =SUM(H26:H42) -> 0 | I43: =SUM(I26:I42) -> 0 | ... M43: =SUM(M26:M42) -> 0 | N43: =SUM(B43:M43) -> 27
A45: META ANUAL: | B45: =+'Informe Gestión Mensual'!B9 -> 7,152 Empresas Turísticas Autorizadas por INTUR.
A47: DEPARTAMENTO / MES | B47: ENERO | C47: FEBRERO | D47: MARZO | E47: ABRIL | F47: MAYO | G47: JUNIO | H47: JULIO | I47: AGOSTO | J47: SEPTIEMBRE | K47: OCTUBRE | L47: NOVIEMBRE | M47: DICIEMBRE | N47: TOTAL
A48: BOACO | B48: 16 | C48: 40 | D48: 44 | E48: 14 | F48: 10 | N48: =SUM(B48:M48) -> 124
A49: CARAZO | B49: 14 | C49: 31 | D49: 63 | E49: 25 | F49: 15 | N49: =SUM(B49:M49) -> 148
...

Sheet Anexo- Intercambios & Ruedas
A1: No. | B1: Intercambios de experiencias realizados | C1: Fecha | D1: Protagonistas
D2: Hombres | E2: Mujeres | F2: Total
A3: 1 | B3: Realizamos Intercambio de Experiencias y Presentación de Casos Exitosos con protagonistas de Managua, Carazo, Granada y Masaya visitan Chontales. | C3: 46079 | D3: 13 | E3: 12 | F3: =+D3+E3 -> 25
A4: 2 | B4: Realizamos Intercambio de Experiencias y Presentación de Casos Exitosos con protagonistas de Managua, Nueva Segovia, Madriz, Estelí, Matagalpa y Jinotega visitan Río San Juan. | C4: 46134 | D4: 4 | E4: 12 | F4: =+D4+E4 -> 16
F5: =+D5+E5 -> 0
F6: =+D6+E6 -> 0
F7: =+D7+E7 -> 0
F8: =+D8+E8 -> 0
D9: =SUM(D3:D8) -> 17 | E9: =SUM(E3:E8) -> 24 | F9: =SUM(F3:F8) -> 41
A16: No. | B16: Ruedas de Negocios | C16: Fecha | D16: Protagonistas
D17: Hombres | E17: Mujeres | F17: Total
A18: 1 | B18: Realizamos Rueda de Negocios con protagonistas de tour operadoras de Carazo, Granada, Managua y Masaya visitan León. | C18: 46073 | D18: 21 | E18: 26 | F18: =+D18+E18 -> 47
A19: 2 | B19: Realizamos Rueda de Negocios Regional con protagonistas de Managua, Carazo, Granada, Masaya y Chontales. | C19: 46080 | D19: 22 | E19: 19 | F19: =+D19+E19 -> 41
A20: 3 | B20: Realizamos Rueda de Negocios con protagonistas de tour operadoras de Granada, Managua y Masaya visitan Carazo. | C20: 46101 | D20: 14 | E20: 8 | F20: =+D20+E20 -> 22
A21: 4 | B21: Realizamos Rueda de Negocios con protagonistas de Empresas en Gestión de Desarrollo Digital de Managua y Chinandega. | C21: 46129 | D21: 26 | E21: 22 | F21: =SUM(D21:E21) -> 48
A22: 5 | B22: Realizamos Rueda de Negocios Regional con protagonistas de Managua, Nueva Segovia, Madriz, Estelí, Matagalpa, Jinotega y Río San Juan. | C22: 46136 | D22: 8 | E22: 16 | F22: =+D22+E22 -> 24
A23: 6 | B23: Realizamos Rueda de Negocios con protagonistas de Empresas en Gestión de Desarrollo Digital de Managua. | C23: 46148 | D23: 21 | E23: 22 | F23: =+D23+E23 -> 43
A24: 7 | B24: Realizamos Rueda de Negocios con tour operadoras de Masaya, Carazo, Granada y León visitan Managua (Expo Pyme). | C24: 46158 | D24: 19 | E24: 12 | F24: =+D24+E24 -> 31
A25: 8 | B25: Realizamos Rueda de Negocios con tour operadoras de Managua, Masaya, Carazo y Granada visitan Madriz. | C25: 46168 | D25: 4 | E25: 13 | F25: =+D25+E25 -> 17
F26: =+D26+E26 -> 0
F27: =+D27+E27 -> 0
F28: =+D28+E28 -> 0
F29: =+D29+E29 -> 0
F30: =+D30+E30 -> 0
F31: =+D31+E31 -> 0
F32: =+D32+E32 -> 0
F33: =+D33+E33 -> 0
F34: =+D34+E34 -> 0
F35: =+D35+E35 -> 0
F36: =+D36+E36 -> 0
F37: =+D37+E37 -> 0
... F43: =+D43+E43 -> 0
D44: =SUM(D18:D43) -> 135 | E44: =SUM(E18:E43) -> 138 | F44: =SUM(F18:F43) -> 273

Sheet ANEXO-ESNNA
A2: ESNNA
A3: Mes | B3: Talleres | C3: Departamento | D3: Hombres | E3: Mujeres | F3: Total
A4: Enero | B4: 2 | C4: Boaco y Granada | D4: 21 | E4: 25 | F4: =SUM(D4:E4) -> 46
A5: Febrero | B5: 7 | C5: Managua (2), Río San Juan, Estelí, Jinotega, Masaya y Madriz | D5: 77 | E5: 113 | F5: =SUM(D5:E5) -> 190
A6: Marzo | B6: 6 | C6: León, Masaya (2), Jinotega (2) y Madriz | D6: 88 | E6: 56 | F6: =SUM(D6:E6) -> 144
A7: Abril | B7: 6 | C7: RACCN (2), Rivas, Matagalpa y Managua (2) | D7: 36 | E7: 119 | F7: =SUM(D7:E7) -> 155
A8: Mayo | B8: 8 | C8: Estelí, Jinotega, Managua (2), Nueva Segovia, Madriz, Rivas y Granada | D8: 93 | E8: 144 | F8: =SUM(D8:E8) -> 237
F9: =SUM(D9:E9) -> 0
F10: =SUM(D10:E10) -> 0
F11: =SUM(D11:E11) -> 0
F12: =SUM(D12:E12) -> 0
F13: =SUM(D13:E13) -> 0
F14: =SUM(D14:E14) -> 0
A15: Total | B15: =SUM(B4:B14) -> 29 | D15: =SUM(D4:D14) -> 315 | E15: =SUM(E4:E14) -> 457 | F15: =SUM(F4:F14) -> 772
